Workbook
Name A: [1]Sheet2!$E$12:$E$14
Name abra: Sheet2!$N$2:$N$28
Name abra_city: Sheet2!$O$2:$O$28
Name abra_zip: Sheet2!$P$2:$P$28
Name agusan_city: Sheet2!$O$29:$O$40
Name agusan_del_sur_city: Sheet2!$O$41:$O$54
Name aklan_city: Sheet2!$O$55:$O$71
Name albay_city: Sheet2!$O$72:$O$89
Name antique_city: Sheet2!$O$90:$O$107
Name apayao_city: Sheet2!$O$108:$O$114
Name aurora_city: Sheet2!$O$116:$O$123
Name basilan_city: Sheet2!$O$124:$O$129
Name bataan_city: Sheet2!$O$131:$O$142
Name batanes_city: Sheet2!$O$144:$O$149
Name batangas_city: Sheet2!$O$150:$O$183
Name beneficiary: Sheet2!$E$12:$E$14
Name benguet_city: Sheet2!$O$185:$O$198
Name biliran_city: Sheet2!$O$200:$O$207
Name bohol_city: Sheet2!$O$208:$O$255
Name bukidnon_city: Sheet2!$O$256:$O$277
Name bulacan_city: Sheet2!$O$279:$O$302
Name cagayan_city: Sheet2!$O$304:$O$332
Name camarines_norte_city: Sheet2!$O$333:$O$344
Name camarines_sur_city: Sheet2!$O$346:$O$382
Name camiguin_city: Sheet2!$O$383:$O$387
Name capiz_city: Sheet2!$O$388:$O$404
Name catanduanes_city: Sheet2!$O$405:$O$415
Name cavite_city: Sheet2!$O$416:$O$438
Name cebu_city: Sheet2!$O$440:$O$492
Name city: Sheet2!$O$2:$O$1657
Name compostela_valley_city: Sheet2!$O$494:$O$504
Name cotabato_city: Sheet2!$O$505
Name country: Sheet2!$E$2
Name davao_del_norte_city: Sheet2!$O$506:$O$516
Name davao_del_sur_city: Sheet2!$O$518:$O$533
Name davao_oriental_city: Sheet2!$O$534:$O$544
Name eastern_samar_city: Sheet2!$O$545:$O$567
Name gender: Sheet2!$A$7:$A$8
Name gender1: Sheet2!$A$7:$A$8
Name guimaras_city: Sheet2!$O$568:$O$572
Name ifugao_city: Sheet2!$O$573:$O$583
Name ilocos_norte_city: Sheet2!$O$584:$O$606
Name ilocos_sur_city: Sheet2!$O$607:$O$640
Name iloilo_city: Sheet2!$O$641:$O$684
Name isabela_city: Sheet2!$O$686:$O$722
Name isabela_city_city: Sheet2!$O$685
Name kalinga_city: Sheet2!$O$723:$O$730
Name la_union_city: Sheet2!$O$732:$O$751
Name laguna_city: Sheet2!$O$753:$O$782
Name lanao_del_norte_city: Sheet2!$O$784:$O$806
Name lanao_del_sur_city: Sheet2!$O$807:$O$845
Name leyte_city: Sheet2!$O$847:$O$889
Name maguindanao_city: Sheet2!$O$890:$O$916
Name manila_city: Sheet2!$O$917:$O$930
Name marinduque_city: Sheet2!$O$931:$O$936
Name masbate_city: Sheet2!$O$937:$O$957
Name misamis_occidental_city: Sheet2!$O$959:$O$975
Name misamis_oriental_city: Sheet2!$O$976:$O$1001
Name mountain_province_city: Sheet2!$O$1002:$O$1011
Name municipality: Sheet2!$O$2:$O$1657

Sheet List
A1: Item Number | B1: Last Name | C1: First Name | D1: Middle Name | E1: Birthdate | F1: Age | G1: Position | H1: Department | I1: Occupation | J1: Cert. No. | K1: AC Info | L1: Civil Status | M1: Gender | N1: Term of Loan (in months) | O1: Actual Date of Receipt | P1: Loan Release Date | Q1: PERIL | R1: Amount of Loan | S1: SURCHARGE | T1: Rate | U1: Premium | W1: ADJ PREM | X1: Rate | Y1: Premium | Z1: PERIL | AA1: TSI | AB1: Rate | AC1: Premium | AD1: PERIL | AE1: TSI | AF1: Rate | AG1: Premium | AH1: PERIL | AI1: TSI | AJ1: Rate | AK1: Premium | AL1: PERIL | AM1: TSI | AN1: Rate | AO1: Premium | AP1: PERIL | AQ1: TSI | AR1: Rate | AS1: Premium | AT1: PERIL | AU1: TSI | AV1: Rate | AW1: Premium | AX1: Net Premium | AZ1: DST | BA1: PTAX | BB1: LGT | BC1: Gross Premium
A2: 1 | F2: =IF(E2="","",INT((YEARFRAC(E2,P2,1)))) | Q2: LR | S2: {=IF(R2="","",_xlfn.IFS(F2<=65,"1",F2<=70,"2",F2<=80,"3"))} | T2: =IF(S2="1",VLOOKUP(N2,Rates!$A$2:$K$37,2,0)*S2,VLOOKUP(N2,Rates!$A$2:$K$37,3,0)*S2) -> #N/A | U2: =IF(R2="","",ROUND((R2*T2)/1000,2)) | W2: =IF(R2="","",BC2-SUM(AZ2:BB2)) | X2: =IF(R2="","",Y2/(R2/1000)) | Y2: =IF(R2="","",(W2-SUM(AC2,AK2,AO2,AS2,AW2,AG2))) | Z2: ADD | AA2: =IF(R2="","",Rates!$N$5) | AB2: =IF(R2="","",(AC2/AA2)*1000) | AC2: =IF(R2="","",W2*Rates!$M$26) | AD2: AMR | AE2: =IF(R2="","",Rates!$N$6) | AF2: =IF(R2="","",AB2*10) | AG2: =IF(N2="","",(AF2*AE2)/1000) | AH2: ABE | AI2: =IF(R2="","",Rates!$N$7) | AJ2: =IF(R2="","",AB2) | AK2: =IF(R2="","",(AJ2*AI2)/1000) | AL2: UMA | AM2: =IF(R2="","",Rates!$N$8) | AN2: =IF(R2="","",(AO2/AM2)*1000) | AO2: =IF(R2="","",W2*Rates!$O$26) | AP2: BA | AQ2: =IF(R2="","",Rates!$N$9) | AR2: =IF(R2="","",(AS2/AQ2)*1000) | AS2: =IF(R2="","",W2*Rates!$P$26) | AT2: MCY | AU2: =IF(R2="","",Rates!$N$10) | AV2: =IF(R2="","",(AW2/AU2)*1000) | AW2: =IF(R2="","",W2*Rates!$Q$26) | AX2: =IF(R2="","",AY2/(1+0.025)) | AY2: =BC2-AZ2 -> #VALUE! | AZ2: =IF(R2="","",Rates!$N$15) | BA2: =IF(R2="","",AX2*2%) | BB2: =IF(R2="","",AX2*0.5%) | BC2: =U2
A3: =IF(B3<>"",COUNTA($B$3:B3)+$A$2,"") | F3: =IF(E3="","",INT((YEARFRAC(E3,P3,1)))) | Q3: LR | S3: {=IF(R3="","",_xlfn.IFS(F3<=65,"1",F3<=70,"2",F3<=80,"3"))} | T3: =IF(S3="1",VLOOKUP(N3,Rates!$A$2:$K$37,2,0)*S3,VLOOKUP(N3,Rates!A1:C37,3,0)*S3) -> #N/A | U3: =IF(R3="","",ROUND((R3*T3)/1000,2)) | W3: =IF(R3="","",BC3-SUM(AZ3:BB3)) | X3: =IF(R3="","",Y3/(R3/1000)) | Y3: =IF(R3="","",(W3-SUM(AC3,AK3,AO3,AS3,AW3,AG3))) | Z3: ADD | AA3: =IF(R3="","",Rates!$N$5) | AB3: =IF(R3="","",(AC3/AA3)*1000) | AC3: =IF(R3="","",W3*Rates!$M$26) | AD3: AMR | AE3: =IF(R3="","",Rates!$N$6) | AF3: =IF(R3="","",AB3*10) | AG3: =IF(N3="","",(AF3*AE3)/1000) | AH3: ABE | AI3: =IF(R3="","",Rates!$N$7) | AJ3: =IF(R3="","",AB3) | AK3: =IF(R3="","",(AJ3*AI3)/1000) | AL3: UMA | AM3: =IF(R3="","",Rates!$N$8) | AN3: =IF(R3="","",(AO3/AM3)*1000) | AO3: =IF(R3="","",W3*Rates!$O$26) | AP3: BA | AQ3: =IF(R3="","",Rates!$N$9) | AR3: =IF(R3="","",(AS3/AQ3)*1000) | AS3: =IF(R3="","",W3*Rates!$P$26) | AT3: MCY | AU3: =IF(R3="","",Rates!$N$10) | AV3: =IF(R3="","",(AW3/AU3)*1000) | AW3: =IF(R3="","",W3*Rates!$Q$26) | AX3: =IF(R3="","",AY3/(1+0.025)) | AY3: =BC3-AZ3 -> #VALUE! | AZ3: =IF(R3="","",Rates!$N$15) | BA3: =IF(R3="","",AX3*2%) | BB3: =IF(R3="","",AX3*0.5%) | BC3: =U3
A4: =IF(B4<>"",COUNTA($B$3:B4)+$A$2,"") | F4: =IF(E4="","",INT((YEARFRAC(E4,P4,1)))) | Q4: LR | S4: {=IF(R4="","",_xlfn.IFS(F4<=65,"1",F4<=70,"2",F4<=80,"3"))} | T4: =IF(S4="1",VLOOKUP(N4,Rates!$A$2:$K$37,2,0)*S4,VLOOKUP(N4,Rates!$A$2:$K$37,3,0)*S4) -> #N/A | U4: =IF(R4="","",ROUND((R4*T4)/1000,2)) | W4: =IF(R4="","",BC4-SUM(AZ4:BB4)) | X4: =IF(R4="","",Y4/(R4/1000)) | Y4: =IF(R4="","",(W4-SUM(AC4,AK4,AO4,AS4,AW4,AG4))) | Z4: ADD | AA4: =IF(R4="","",Rates!$N$5) | AB4: =IF(R4="","",(AC4/AA4)*1000) | AC4: =IF(R4="","",W4*Rates!$M$26) | AD4: AMR | AE4: =IF(R4="","",Rates!$N$6) | AF4: =IF(R4="","",AB4*10) | AG4: =IF(N4="","",(AF4*AE4)/1000) | AH4: ABE | AI4: =IF(R4="","",Rates!$N$7) | AJ4: =IF(R4="","",AB4) | AK4: =IF(R4="","",(AJ4*AI4)/1000) | AL4: UMA | AM4: =IF(R4="","",Rates!$N$8) | AN4: =IF(R4="","",(AO4/AM4)*1000) | AO4: =IF(R4="","",W4*Rates!$O$26) | AP4: BA | AQ4: =IF(R4="","",Rates!$N$9) | AR4: =IF(R4="","",(AS4/AQ4)*1000) | AS4: =IF(R4="","",W4*Rates!$P$26) | AT4: MCY | AU4: =IF(R4="","",Rates!$N$10) | AV4: =IF(R4="","",(AW4/AU4)*1000) | AW4: =IF(R4="","",W4*Rates!$Q$26) | AX4: =IF(R4="","",AY4/(1+0.025)) | AY4: =BC4-AZ4 -> #VALUE! | AZ4: =IF(R4="","",Rates!$N$15) | BA4: =IF(R4="","",AX4*2%) | BB4: =IF(R4="","",AX4*0.5%) | BC4: =U4
A5: =IF(B5<>"",COUNTA($B$3:B5)+$A$2,"") | F5: =IF(E5="","",INT((YEARFRAC(E5,P5,1)))) | Q5: LR | S5: {=IF(R5="","",_xlfn.IFS(F5<=65,"1",F5<=70,"2",F5<=80,"3"))} | T5: =IF(S5="1",VLOOKUP(N5,Rates!$A$2:$K$37,2,0)*S5,VLOOKUP(N5,Rates!$A$2:$K$37,3,0)*S5) -> #N/A | U5: =IF(R5="","",ROUND((R5*T5)/1000,2)) | W5: =IF(R5="","",BC5-SUM(AZ5:BB5)) | X5: =IF(R5="","",Y5/(R5/1000)) | Y5: =IF(R5="","",(W5-SUM(AC5,AK5,AO5,AS5,AW5,AG5))) | Z5: ADD | AA5: =IF(R5="","",Rates!$N$5) | AB5: =IF(R5="","",(AC5/AA5)*1000) | AC5: =IF(R5="","",W5*Rates!$M$26) | AD5: AMR | AE5: =IF(R5="","",Rates!$N$6) | AF5: =IF(R5="","",AB5*10) | AG5: =IF(N5="","",(AF5*AE5)/1000) | AH5: ABE | AI5: =IF(R5="","",Rates!$N$7) | AJ5: =IF(R5="","",AB5) | AK5: =IF(R5="","",(AJ5*AI5)/1000) | AL5: UMA | AM5: =IF(R5="","",Rates!$N$8) | AN5: =IF(R5="","",(AO5/AM5)*1000) | AO5: =IF(R5="","",W5*Rates!$O$26) | AP5: BA | AQ5: =IF(R5="","",Rates!$N$9) | AR5: =IF(R5="","",(AS5/AQ5)*1000) | AS5: =IF(R5="","",W5*Rates!$P$26) | AT5: MCY | AU5: =IF(R5="","",Rates!$N$10) | AV5: =IF(R5="","",(AW5/AU5)*1000) | AW5: =IF(R5="","",W5*Rates!$Q$26) | AX5: =IF(R5="","",AY5/(1+0.025)) | AY5: =BC5-AZ5 -> #VALUE! | AZ5: =IF(R5="","",Rates!$N$15) | BA5: =IF(R5="","",AX5*2%) | BB5: =IF(R5="","",AX5*0.5%) | BC5: =U5
A6: =IF(B6<>"",COUNTA($B$3:B6)+$A$2,"") | F6: =IF(E6="","",INT((YEARFRAC(E6,P6,1)))) | Q6: LR | S6: {=IF(R6="","",_xlfn.IFS(F6<=65,"1",F6<=70,"2",F6<=80,"3"))} | T6: =IF(S6="1",VLOOKUP(N6,Rates!$A$2:$K$37,2,0)*S6,VLOOKUP(N6,Rates!$A$2:$K$37,3,0)*S6) -> #N/A | U6: =IF(R6="","",ROUND((R6*T6)/1000,2)) | W6: =IF(R6="","",BC6-SUM(AZ6:BB6)) | X6: =IF(R6="","",Y6/(R6/1000)) | Y6: =IF(R6="","",(W6-SUM(AC6,AK6,AO6,AS6,AW6,AG6))) | Z6: ADD | AA6: =IF(R6="","",Rates!$N$5) | AB6: =IF(R6="","",(AC6/AA6)*1000) | AC6: =IF(R6="","",W6*Rates!$M$26) | AD6: AMR | AE6: =IF(R6="","",Rates!$N$6) | AF6: =IF(R6="","",AB6*10) | AG6: =IF(N6="","",(AF6*AE6)/1000) | AH6: ABE | AI6: =IF(R6="","",Rates!$N$7) | AJ6: =IF(R6="","",AB6) | AK6: =IF(R6="","",(AJ6*AI6)/1000) | AL6: UMA | AM6: =IF(R6="","",Rates!$N$8) | AN6: =IF(R6="","",(AO6/AM6)*1000) | AO6: =IF(R6="","",W6*Rates!$O$26) | AP6: BA | AQ6: =IF(R6="","",Rates!$N$9) | AR6: =IF(R6="","",(AS6/AQ6)*1000) | AS6: =IF(R6="","",W6*Rates!$P$26) | AT6: MCY | AU6: =IF(R6="","",Rates!$N$10) | AV6: =IF(R6="","",(AW6/AU6)*1000) | AW6: =IF(R6="","",W6*Rates!$Q$26) | AX6: =IF(R6="","",AY6/(1+0.025)) | AY6: =BC6-AZ6 -> #VALUE! | AZ6: =IF(R6="","",Rates!$N$15) | BA6: =IF(R6="","",AX6*2%) | BB6: =IF(R6="","",AX6*0.5%) | BC6: =U6
A7: =IF(B7<>"",COUNTA($B$3:B7)+$A$2,"") | F7: =IF(E7="","",INT((YEARFRAC(E7,P7,1)))) | Q7: LR | S7: {=IF(R7="","",_xlfn.IFS(F7<=65,"1",F7<=70,"2",F7<=80,"3"))} | T7: =IF(S7="1",VLOOKUP(N7,Rates!$A$2:$K$37,2,0)*S7,VLOOKUP(N7,Rates!$A$2:$K$37,3,0)*S7) -> #N/A | U7: =IF(R7="","",ROUND((R7*T7)/1000,2)) | W7: =IF(R7="","",BC7-SUM(AZ7:BB7)) | X7: =IF(R7="","",Y7/(R7/1000)) | Y7: =IF(R7="","",(W7-SUM(AC7,AK7,AO7,AS7,AW7,AG7))) | Z7: ADD | AA7: =IF(R7="","",Rates!$N$5) | AB7: =IF(R7="","",(AC7/AA7)*1000) | AC7: =IF(R7="","",W7*Rates!$M$26) | AD7: AMR | AE7: =IF(R7="","",Rates!$N$6) | AF7: =IF(R7="","",AB7*10) | AG7: =IF(N7="","",(AF7*AE7)/1000) | AH7: ABE | AI7: =IF(R7="","",Rates!$N$7) | AJ7: =IF(R7="","",AB7) | AK7: =IF(R7="","",(AJ7*AI7)/1000) | AL7: UMA | AM7: =IF(R7="","",Rates!$N$8) | AN7: =IF(R7="","",(AO7/AM7)*1000) | AO7: =IF(R7="","",W7*Rates!$O$26) | AP7: BA | AQ7: =IF(R7="","",Rates!$N$9) | AR7: =IF(R7="","",(AS7/AQ7)*1000) | AS7: =IF(R7="","",W7*Rates!$P$26) | AT7: MCY | AU7: =IF(R7="","",Rates!$N$10) | AV7: =IF(R7="","",(AW7/AU7)*1000) | AW7: =IF(R7="","",W7*Rates!$Q$26) | AX7: =IF(R7="","",AY7/(1+0.025)) | AY7: =BC7-AZ7 -> #VALUE! | AZ7: =IF(R7="","",Rates!$N$15) | BA7: =IF(R7="","",AX7*2%) | BB7: =IF(R7="","",AX7*0.5%) | BC7: =U7
A8: =IF(B8<>"",COUNTA($B$3:B8)+$A$2,"") | F8: =IF(E8="","",INT((YEARFRAC(E8,P8,1)))) | Q8: LR | S8: {=IF(R8="","",_xlfn.IFS(F8<=65,"1",F8<=70,"2",F8<=80,"3"))} | T8: =IF(S8="1",VLOOKUP(N8,Rates!$A$2:$K$37,2,0)*S8,VLOOKUP(N8,Rates!$A$2:$K$37,3,0)*S8) -> #N/A | U8: =IF(R8="","",ROUND((R8*T8)/1000,2)) | W8: =IF(R8="","",BC8-SUM(AZ8:BB8)) | X8: =IF(R8="","",Y8/(R8/1000)) | Y8: =IF(R8="","",(W8-SUM(AC8,AK8,AO8,AS8,AW8,AG8))) | Z8: ADD | AA8: =IF(R8="","",Rates!$N$5) | AB8: =IF(R8="","",(AC8/AA8)*1000) | AC8: =IF(R8="","",W8*Rates!$M$26) | AD8: AMR | AE8: =IF(R8="","",Rates!$N$6) | AF8: =IF(R8="","",AB8*10) | AG8: =IF(N8="","",(AF8*AE8)/1000) | AH8: ABE | AI8: =IF(R8="","",Rates!$N$7) | AJ8: =IF(R8="","",AB8) | AK8: =IF(R8="","",(AJ8*AI8)/1000) | AL8: UMA | AM8: =IF(R8="","",Rates!$N$8) | AN8: =IF(R8="","",(AO8/AM8)*1000) | AO8: =IF(R8="","",W8*Rates!$O$26) | AP8: BA | AQ8: =IF(R8="","",Rates!$N$9) | AR8: =IF(R8="","",(AS8/AQ8)*1000) | AS8: =IF(R8="","",W8*Rates!$P$26) | AT8: MCY | AU8: =IF(R8="","",Rates!$N$10) | AV8: =IF(R8="","",(AW8/AU8)*1000) | AW8: =IF(R8="","",W8*Rates!$Q$26) | AX8: =IF(R8="","",AY8/(1+0.025)) | AY8: =BC8-AZ8 -> #VALUE! | AZ8: =IF(R8="","",Rates!$N$15) | BA8: =IF(R8="","",AX8*2%) | BB8: =IF(R8="","",AX8*0.5%) | BC8: =U8
A9: =IF(B9<>"",COUNTA($B$3:B9)+$A$2,"") | F9: =IF(E9="","",INT((YEARFRAC(E9,P9,1)))) | Q9: LR | S9: {=IF(R9="","",_xlfn.IFS(F9<=65,"1",F9<=70,"2",F9<=80,"3"))} | T9: =IF(S9="1",VLOOKUP(N9,Rates!$A$2:$K$37,2,0)*S9,VLOOKUP(N9,Rates!$A$2:$K$37,3,0)*S9) -> #N/A | U9: =IF(R9="","",ROUND((R9*T9)/1000,2)) | W9: =IF(R9="","",BC9-SUM(AZ9:BB9)) | X9: =IF(R9="","",Y9/(R9/1000)) | Y9: =IF(R9="","",(W9-SUM(AC9,AK9,AO9,AS9,AW9,AG9))) | Z9: ADD | AA9: =IF(R9="","",Rates!$N$5) | AB9: =IF(R9="","",(AC9/AA9)*1000) | AC9: =IF(R9="","",W9*Rates!$M$26) | AD9: AMR | AE9: =IF(R9="","",Rates!$N$6) | AF9: =IF(R9="","",AB9*10) | AG9: =IF(N9="","",(AF9*AE9)/1000) | AH9: ABE | AI9: =IF(R9="","",Rates!$N$7) | AJ9: =IF(R9="","",AB9) | AK9: =IF(R9="","",(AJ9*AI9)/1000) | AL9: UMA | AM9: =IF(R9="","",Rates!$N$8) | AN9: =IF(R9="","",(AO9/AM9)*1000) | AO9: =IF(R9="","",W9*Rates!$O$26) | AP9: BA | AQ9: =IF(R9="","",Rates!$N$9) | AR9: =IF(R9="","",(AS9/AQ9)*1000) | AS9: =IF(R9="","",W9*Rates!$P$26) | AT9: MCY | AU9: =IF(R9="","",Rates!$N$10) | AV9: =IF(R9="","",(AW9/AU9)*1000) | AW9: =IF(R9="","",W9*Rates!$Q$26) | AX9: =IF(R9="","",AY9/(1+0.025)) | AY9: =BC9-AZ9 -> #VALUE! | AZ9: =IF(R9="","",Rates!$N$15) | BA9: =IF(R9="","",AX9*2%) | BB9: =IF(R9="","",AX9*0.5%) | BC9: =U9
A10: =IF(B10<>"",COUNTA($B$3:B10)+$A$2,"") | F10: =IF(E10="","",INT((YEARFRAC(E10,P10,1)))) | Q10: LR | S10: {=IF(R10="","",_xlfn.IFS(F10<=65,"1",F10<=70,"2",F10<=80,"3"))} | T10: =IF(S10="1",VLOOKUP(N10,Rates!$A$2:$K$37,2,0)*S10,VLOOKUP(N10,Rates!$A$2:$K$37,3,0)*S10) -> #N/A | U10: =IF(R10="","",ROUND((R10*T10)/1000,2)) | W10: =IF(R10="","",BC10-SUM(AZ10:BB10)) | X10: =IF(R10="","",Y10/(R10/1000)) | Y10: =IF(R10="","",(W10-SUM(AC10,AK10,AO10,AS10,AW10,AG10))) | Z10: ADD | AA10: =IF(R10="","",Rates!$N$5) | AB10: =IF(R10="","",(AC10/AA10)*1000) | AC10: =IF(R10="","",W10*Rates!$M$26) | AD10: AMR | AE10: =IF(R10="","",Rates!$N$6) | AF10: =IF(R10="","",AB10*10) | AG10: =IF(N10="","",(AF10*AE10)/1000) | AH10: ABE | AI10: =IF(R10="","",Rates!$N$7) | AJ10: =IF(R10="","",AB10) | AK10: =IF(R10="","",(AJ10*AI10)/1000) | AL10: UMA | AM10: =IF(R10="","",Rates!$N$8) | AN10: =IF(R10="","",(AO10/AM10)*1000) | AO10: =IF(R10="","",W10*Rates!$O$26) | AP10: BA | AQ10: =IF(R10="","",Rates!$N$9) | AR10: =IF(R10="","",(AS10/AQ10)*1000) | AS10: =IF(R10="","",W10*Rates!$P$26) | AT10: MCY | AU10: =IF(R10="","",Rates!$N$10) | AV10: =IF(R10="","",(AW10/AU10)*1000) | AW10: =IF(R10="","",W10*Rates!$Q$26) | AX10: =IF(R10="","",AY10/(1+0.025)) | AY10: =BC10-AZ10 -> #VALUE! | AZ10: =IF(R10="","",Rates!$N$15) | BA10: =IF(R10="","",AX10*2%) | BB10: =IF(R10="","",AX10*0.5%) | BC10: =U10
A11: =IF(B11<>"",COUNTA($B$3:B11)+$A$2,"") | F11: =IF(E11="","",INT((YEARFRAC(E11,P11,1)))) | Q11: LR | S11: {=IF(R11="","",_xlfn.IFS(F11<=65,"1",F11<=70,"2",F11<=80,"3"))} | T11: =IF(S11="1",VLOOKUP(N11,Rates!$A$2:$K$37,2,0)*S11,VLOOKUP(N11,Rates!$A$2:$K$37,3,0)*S11) -> #N/A | U11: =IF(R11="","",ROUND((R11*T11)/1000,2)) | W11: =IF(R11="","",BC11-SUM(AZ11:BB11)) | X11: =IF(R11="","",Y11/(R11/1000)) | Y11: =IF(R11="","",(W11-SUM(AC11,AK11,AO11,AS11,AW11,AG11))) | Z11: ADD | AA11: =IF(R11="","",Rates!$N$5) | AB11: =IF(R11="","",(AC11/AA11)*1000) | AC11: =IF(R11="","",W11*Rates!$M$26) | AD11: AMR | AE11: =IF(R11="","",Rates!$N$6) | AF11: =IF(R11="","",AB11*10) | AG11: =IF(N11="","",(AF11*AE11)/1000) | AH11: ABE | AI11: =IF(R11="","",Rates!$N$7) | AJ11: =IF(R11="","",AB11) | AK11: =IF(R11="","",(AJ11*AI11)/1000) | AL11: UMA | AM11: =IF(R11="","",Rates!$N$8) | AN11: =IF(R11="","",(AO11/AM11)*1000) | AO11: =IF(R11="","",W11*Rates!$O$26) | AP11: BA | AQ11: =IF(R11="","",Rates!$N$9) | AR11: =IF(R11="","",(AS11/AQ11)*1000) | AS11: =IF(R11="","",W11*Rates!$P$26) | AT11: MCY | AU11: =IF(R11="","",Rates!$N$10) | AV11: =IF(R11="","",(AW11/AU11)*1000) | AW11: =IF(R11="","",W11*Rates!$Q$26) | AX11: =IF(R11="","",AY11/(1+0.025)) | AY11: =BC11-AZ11 -> #VALUE! | AZ11: =IF(R11="","",Rates!$N$15) | BA11: =IF(R11="","",AX11*2%) | BB11: =IF(R11="","",AX11*0.5%) | BC11: =U11
A12: =IF(B12<>"",COUNTA($B$3:B12)+$A$2,"") | F12: =IF(E12="","",INT((YEARFRAC(E12,P12,1)))) | Q12: LR | S12: {=IF(R12="","",_xlfn.IFS(F12<=65,"1",F12<=70,"2",F12<=80,"3"))} | T12: =IF(S12="1",VLOOKUP(N12,Rates!$A$2:$K$37,2,0)*S12,VLOOKUP(N12,Rates!$A$2:$K$37,3,0)*S12) -> #N/A | U12: =IF(R12="","",ROUND((R12*T12)/1000,2)) | W12: =IF(R12="","",BC12-SUM(AZ12:BB12)) | X12: =IF(R12="","",Y12/(R12/1000)) | Y12: =IF(R12="","",(W12-SUM(AC12,AK12,AO12,AS12,AW12,AG12))) | Z12: ADD | AA12: =IF(R12="","",Rates!$N$5) | AB12: =IF(R12="","",(AC12/AA12)*1000) | AC12: =IF(R12="","",W12*Rates!$M$26) | AD12: AMR | AE12: =IF(R12="","",Rates!$N$6) | AF12: =IF(R12="","",AB12*10) | AG12: =IF(N12="","",(AF12*AE12)/1000) | AH12: ABE | AI12: =IF(R12="","",Rates!$N$7) | AJ12: =IF(R12="","",AB12) | AK12: =IF(R12="","",(AJ12*AI12)/1000) | AL12: UMA | AM12: =IF(R12="","",Rates!$N$8) | AN12: =IF(R12="","",(AO12/AM12)*1000) | AO12: =IF(R12="","",W12*Rates!$O$26) | AP12: BA | AQ12: =IF(R12="","",Rates!$N$9) | AR12: =IF(R12="","",(AS12/AQ12)*1000) | AS12: =IF(R12="","",W12*Rates!$P$26) | AT12: MCY | AU12: =IF(R12="","",Rates!$N$10) | AV12: =IF(R12="","",(AW12/AU12)*1000) | AW12: =IF(R12="","",W12*Rates!$Q$26) | AX12: =IF(R12="","",AY12/(1+0.025)) | AY12: =BC12-AZ12 -> #VALUE! | AZ12: =IF(R12="","",Rates!$N$15) | BA12: =IF(R12="","",AX12*2%) | BB12: =IF(R12="","",AX12*0.5%) | BC12: =U12
A13: =IF(B13<>"",COUNTA($B$3:B13)+$A$2,"") | F13: =IF(E13="","",INT((YEARFRAC(E13,P13,1)))) | Q13: LR | S13: {=IF(R13="","",_xlfn.IFS(F13<=65,"1",F13<=70,"2",F13<=80,"3"))} | T13: =IF(S13="1",VLOOKUP(N13,Rates!$A$2:$K$37,2,0)*S13,VLOOKUP(N13,Rates!$A$2:$K$37,3,0)*S13) -> #N/A | U13: =IF(R13="","",ROUND((R13*T13)/1000,2)) | W13: =IF(R13="","",BC13-SUM(AZ13:BB13)) | X13: =IF(R13="","",Y13/(R13/1000)) | Y13: =IF(R13="","",(W13-SUM(AC13,AK13,AO13,AS13,AW13,AG13))) | Z13: ADD | AA13: =IF(R13="","",Rates!$N$5) | AB13: =IF(R13="","",(AC13/AA13)*1000) | AC13: =IF(R13="","",W13*Rates!$M$26) | AD13: AMR | AE13: =IF(R13="","",Rates!$N$6) | AF13: =IF(R13="","",AB13*10) | AG13: =IF(N13="","",(AF13*AE13)/1000) | AH13: ABE | AI13: =IF(R13="","",Rates!$N$7) | AJ13: =IF(R13="","",AB13) | AK13: =IF(R13="","",(AJ13*AI13)/1000) | AL13: UMA | AM13: =IF(R13="","",Rates!$N$8) | AN13: =IF(R13="","",(AO13/AM13)*1000) | AO13: =IF(R13="","",W13*Rates!$O$26) | AP13: BA | AQ13: =IF(R13="","",Rates!$N$9) | AR13: =IF(R13="","",(AS13/AQ13)*1000) | AS13: =IF(R13="","",W13*Rates!$P$26) | AT13: MCY | AU13: =IF(R13="","",Rates!$N$10) | AV13: =IF(R13="","",(AW13/AU13)*1000) | AW13: =IF(R13="","",W13*Rates!$Q$26) | AX13: =IF(R13="","",AY13/(1+0.025)) | AY13: =BC13-AZ13 -> #VALUE! | AZ13: =IF(R13="","",Rates!$N$15) | BA13: =IF(R13="","",AX13*2%) | BB13: =IF(R13="","",AX13*0.5%) | BC13: =U13
A14: =IF(B14<>"",COUNTA($B$3:B14)+$A$2,"") | F14: =IF(E14="","",INT((YEARFRAC(E14,P14,1)))) | Q14: LR | S14: {=IF(R14="","",_xlfn.IFS(F14<=65,"1",F14<=70,"2",F14<=80,"3"))} | T14: =IF(S14="1",VLOOKUP(N14,Rates!$A$2:$K$37,2,0)*S14,VLOOKUP(N14,Rates!$A$2:$K$37,3,0)*S14) -> #N/A | U14: =IF(R14="","",ROUND((R14*T14)/1000,2)) | W14: =IF(R14="","",BC14-SUM(AZ14:BB14)) | X14: =IF(R14="","",Y14/(R14/1000)) | Y14: =IF(R14="","",(W14-SUM(AC14,AK14,AO14,AS14,AW14,AG14))) | Z14: ADD | AA14: =IF(R14="","",Rates!$N$5) | AB14: =IF(R14="","",(AC14/AA14)*1000) | AC14: =IF(R14="","",W14*Rates!$M$26) | AD14: AMR | AE14: =IF(R14="","",Rates!$N$6) | AF14: =IF(R14="","",AB14*10) | AG14: =IF(N14="","",(AF14*AE14)/1000) | AH14: ABE | AI14: =IF(R14="","",Rates!$N$7) | AJ14: =IF(R14="","",AB14) | AK14: =IF(R14="","",(AJ14*AI14)/1000) | AL14: UMA | AM14: =IF(R14="","",Rates!$N$8) | AN14: =IF(R14="","",(AO14/AM14)*1000) | AO14: =IF(R14="","",W14*Rates!$O$26) | AP14: BA | AQ14: =IF(R14="","",Rates!$N$9) | AR14: =IF(R14="","",(AS14/AQ14)*1000) | AS14: =IF(R14="","",W14*Rates!$P$26) | AT14: MCY | AU14: =IF(R14="","",Rates!$N$10) | AV14: =IF(R14="","",(AW14/AU14)*1000) | AW14: =IF(R14="","",W14*Rates!$Q$26) | AX14: =IF(R14="","",AY14/(1+0.025)) | AY14: =BC14-AZ14 -> #VALUE! | AZ14: =IF(R14="","",Rates!$N$15) | BA14: =IF(R14="","",AX14*2%) | BB14: =IF(R14="","",AX14*0.5%) | BC14: =U14
A15: =IF(B15<>"",COUNTA($B$3:B15)+$A$2,"") | F15: =IF(E15="","",INT((YEARFRAC(E15,P15,1)))) | Q15: LR | S15: {=IF(R15="","",_xlfn.IFS(F15<=65,"1",F15<=70,"2",F15<=80,"3"))} | T15: =IF(S15="1",VLOOKUP(N15,Rates!$A$2:$K$37,2,0)*S15,VLOOKUP(N15,Rates!$A$2:$K$37,3,0)*S15) -> #N/A | U15: =IF(R15="","",ROUND((R15*T15)/1000,2)) | W15: =IF(R15="","",BC15-SUM(AZ15:BB15)) | X15: =IF(R15="","",Y15/(R15/1000)) | Y15: =IF(R15="","",(W15-SUM(AC15,AK15,AO15,AS15,AW15,AG15))) | Z15: ADD | AA15: =IF(R15="","",Rates!$N$5) | AB15: =IF(R15="","",(AC15/AA15)*1000) | AC15: =IF(R15="","",W15*Rates!$M$26) | AD15: AMR | AE15: =IF(R15="","",Rates!$N$6) | AF15: =IF(R15="","",AB15*10) | AG15: =IF(N15="","",(AF15*AE15)/1000) | AH15: ABE | AI15: =IF(R15="","",Rates!$N$7) | AJ15: =IF(R15="","",AB15) | AK15: =IF(R15="","",(AJ15*AI15)/1000) | AL15: UMA | AM15: =IF(R15="","",Rates!$N$8) | AN15: =IF(R15="","",(AO15/AM15)*1000) | AO15: =IF(R15="","",W15*Rates!$O$26) | AP15: BA | AQ15: =IF(R15="","",Rates!$N$9) | AR15: =IF(R15="","",(AS15/AQ15)*1000) | AS15: =IF(R15="","",W15*Rates!$P$26) | AT15: MCY | AU15: =IF(R15="","",Rates!$N$10) | AV15: =IF(R15="","",(AW15/AU15)*1000) | AW15: =IF(R15="","",W15*Rates!$Q$26) | AX15: =IF(R15="","",AY15/(1+0.025)) | AY15: =BC15-AZ15 -> #VALUE! | AZ15: =IF(R15="","",Rates!$N$15) | BA15: =IF(R15="","",AX15*2%) | BB15: =IF(R15="","",AX15*0.5%) | BC15: =U15
... A1000: =IF(B1000<>"",COUNTA($B$3:B1000)+$A$2,"") | F1000: =IF(E1000="","",INT((YEARFRAC(E1000,P1000,1)))) | Q1000: LR | S1000: {=IF(R1000="","",_xlfn.IFS(F1000<=65,"1",F1000<=70,"2",F1000<=80,"3"))} | T1000: =IF(S1000="1",VLOOKUP(N1000,Rates!$A$2:$K$37,2,0)*S1000,VLOOKUP(N1000,Rates!$A$2:$K$37,3,0)*S1000) -> #N/A | U1000: =IF(R1000="","",ROUND((R1000*T1000)/1000,2)) | W1000: =IF(R1000="","",BC1000-SUM(AZ1000:BB1000)) | X1000: =IF(R1000="","",Y1000/(R1000/1000)) | Y1000: =IF(R1000="","",(W1000-SUM(AC1000,AK1000,AO1000,AS1000,AW1000,AG1000))) | Z1000: ADD | AA1000: =IF(R1000="","",Rates!$N$5) | AB1000: =IF(R1000="","",(AC1000/AA1000)*1000) | AC1000: =IF(R1000="","",W1000*Rates!$M$26) | AD1000: AMR | AE1000: =IF(R1000="","",Rates!$N$6) | AF1000: =IF(R1000="","",AB1000*10) | AG1000: =IF(N1000="","",(AF1000*AE1000)/1000) | AH1000: ABE | AI1000: =IF(R1000="","",Rates!$N$7) | AJ1000: =IF(R1000="","",AB1000) | AK1000: =IF(R1000="","",(AJ1000*AI1000)/1000) | AL1000: UMA | AM1000: =IF(R1000="","",Rates!$N$8) | AN1000: =IF(R1000="","",(AO1000/AM1000)*1000) | AO1000: =IF(R1000="","",W1000*Rates!$O$26) | AP1000: BA | AQ1000: =IF(R1000="","",Rates!$N$9) | AR1000: =IF(R1000="","",(AS1000/AQ1000)*1000) | AS1000: =IF(R1000="","",W1000*Rates!$P$26) | AT1000: MCY | AU1000: =IF(R1000="","",Rates!$N$10) | AV1000: =IF(R1000="","",(AW1000/AU1000)*1000) | AW1000: =IF(R1000="","",W1000*Rates!$Q$26) | AX1000: =IF(R1000="","",AY1000/(1+0.025)) | AY1000: =BC1000-AZ1000 -> #VALUE! | AZ1000: =IF(R1000="","",Rates!$N$15) | BA1000: =IF(R1000="","",AX1000*2%) | BB1000: =IF(R1000="","",AX1000*0.5%) | BC1000: =U1000
A1001: * | AX1001: =IF(R1001="","",AY1001/(1+0.025)) | AY1001: =BC1001-AZ1001 -> 0
A1002: =IF(B1002<>"",COUNTA($B$3:B1002)+$A$2,"") | AX1002: =IF(R1002="","",AY1002/(1+0.025)) | AY1002: =BC1002-AZ1002 -> 0
A1003: =IF(B1003<>"",COUNTA($B$3:B1003)+$A$2,"") | AX1003: =IF(R1003="","",AY1003/(1+0.025)) | AY1003: =BC1003-AZ1003 -> 0
A1004: =IF(B1004<>"",COUNTA($B$3:B1004)+$A$2,"") | AX1004: =IF(R1004="","",AY1004/(1+0.025)) | AY1004: =BC1004-AZ1004 -> 0
A1005: =IF(B1005<>"",COUNTA($B$3:B1005)+$A$2,"") | AX1005: =IF(R1005="","",AY1005/(1+0.025)) | AY1005: =BC1005-AZ1005 -> 0
A1006: =IF(B1006<>"",COUNTA($B$3:B1006)+$A$2,"") | AX1006: =IF(R1006="","",AY1006/(1+0.025)) | AY1006: =BC1006-AZ1006 -> 0
A1007: =IF(B1007<>"",COUNTA($B$3:B1007)+$A$2,"") | AX1007: =IF(R1007="","",AY1007/(1+0.025)) | AY1007: =BC1007-AZ1007 -> 0
A1008: =IF(B1008<>"",COUNTA($B$3:B1008)+$A$2,"") | AX1008: =IF(R1008="","",AY1008/(1+0.025)) | AY1008: =BC1008-AZ1008 -> 0
A1009: =IF(B1009<>"",COUNTA($B$3:B1009)+$A$2,"") | AX1009: =IF(R1009="","",AY1009/(1+0.025)) | AY1009: =BC1009-AZ1009 -> 0
A1010: =IF(B1010<>"",COUNTA($B$3:B1010)+$A$2,"") | AX1010: =IF(R1010="","",AY1010/(1+0.025)) | AY1010: =BC1010-AZ1010 -> 0
A1011: =IF(B1011<>"",COUNTA($B$3:B1011)+$A$2,"") | AX1011: =IF(R1011="","",AY1011/(1+0.025)) | AY1011: =BC1011-AZ1011 -> 0
A1012: =IF(B1012<>"",COUNTA($B$3:B1012)+$A$2,"") | AX1012: =IF(R1012="","",AY1012/(1+0.025)) | AY1012: =BC1012-AZ1012 -> 0
A1013: =IF(B1013<>"",COUNTA($B$3:B1013)+$A$2,"") | AX1013: =IF(R1013="","",AY1013/(1+0.025)) | AY1013: =BC1013-AZ1013 -> 0
... A10000: =IF(B10000<>"",COUNTA($B$3:B10000)+$A$2,"") | AX10000: =IF(R10000="","",AY10000/(1+0.025)) | AY10000: =BC10000-AZ10000 -> 0

Sheet Summary_Aggregate
B2: SUM INSURED/PERSON | C2: TOTAL SUM INSURED | D2: PREMIUM PER PERIL
A3: LRI | C3: =SUM(List!R2:R1048576) -> 0 | D3: =SUM(List!Y2:Y1000) -> 0
A4: ADD | B4: =Rates!N5 -> 50000 | C4: =B4*Rates!$M$2 -> 0 | D4: =SUM(List!AC2:AC1000) -> 0
A5: AMR | B5: =Rates!N6 -> 5000 | C5: =B5*Rates!$M$2 -> 0 | D5: =SUM(List!AG2:AG1000) -> 0
A6: ABE | B6: =Rates!N7 -> 5000 | C6: =B6*Rates!$M$2 -> 0 | D6: =SUM(List!AK2:AK1000) -> 0
A7: UMA | B7: =Rates!N8 -> 50000 | C7: =B7*Rates!$M$2 -> 0 | D7: =SUM(List!AO2:AO1000) -> 0
A8: BA | B8: =Rates!N9 -> 10000 | C8: =B8*Rates!$M$2 -> 0 | D8: =SUM(List!AS2:AS1000) -> 0
A9: MCY | B9: =Rates!N10 -> 25000 | C9: =B9*Rates!$M$2 -> 0 | D9: =SUM(List!AW2:AW1000) -> 0
C11: NET PREMIUM | D11: =SUM(List!AX2:AX10000) -> 0
C12: DST | D12: =SUM(List!AZ2:AZ10000) -> 0
C13: PTAX | D13: =SUM(List!BA2:BA10000) -> 0
C14: LGT | D14: =SUM(List!BB2:BB10000) -> 0
C15: GROSS PREMIUM | D15: =SUM(List!BC2:BC1000) -> 0

Sheet Sheet2
A1: Occupation | C1: Cooperative? | E1: Country | J1: Province Name | N1: PROVINCE | O1: MUNICIPALITY | P1: ZIP CODE
A2: MICROENTREPRENEUR | C2: Yes | E2: PHILIPPINES | J2: ABRA | N2: ABRA | O2: BANGUED | P2: 2800
A3: AGRICULTURE | C3: No | J3: AGUSAN DEL NORTE | N3: ABRA | O3: BOLINEY | P3: 2815
A4: DAILY WAGE EARNER | J4: AGUSAN DEL SUR | N4: ABRA | O4: BUCAY | P4: 2805
J5: AKLAN | N5: ABRA | O5: BUCLOC | P5: 2817
A6: Gender | J6: ALBAY | N6: ABRA | O6: DAGUIOMAN | P6: 2816
A7: MALE | J7: ANTIQUE | N7: ABRA | O7: DANGLAS | P7: 2825
A8: FEMALE | J8: APAYAO | N8: ABRA | O8: DOLORES | P8: 2801
J9: AURORA | N9: ABRA | O9: LA PAZ | P9: 2826
J10: BASILAN | N10: ABRA | O10: LACUB | P10: 2821
A11: Term of loan | C11: Civil Status | E11: Beneficiary Tag | J11: BATAAN | N11: ABRA | O11: LAGANGILANG | P11: 2902
A12: 1 | C12: MARRIED | E12: INSURED | J12: BATANES | N12: ABRA | O12: LAGAYAN | P12: 2824
A13: 2 | C13: SINGLE | E13: BENEFICIARY | J13: BATANGAS | N13: ABRA | O13: LANGIDEN | P13: 2807
A14: 3 | C14: WIDOWED | E14: BOTH | J14: BENGUET | N14: ABRA | O14: LICUAN-BAAY (LICUAN) | P14: 2819
A15: 4 | C15: DIVORCED | J15: BILIRAN | N15: ABRA | O15: LUBA | P15: 2813
A16: 5 | C16: LEGALLY SEPARATED | J16: BOHOL | N16: ABRA | O16: MALIBCONG | P16: 2820
A17: 6 | J17: BUKIDNON | N17: ABRA | O17: MANABO | P17: 2810
A18: 7 | J18: BULACAN | N18: ABRA | O18: PEÑARRUBIA | P18: 2804
A19: 8 | J19: CAGAYAN | N19: ABRA | O19: PIDIGAN | P19: 2806
A20: 9 | J20: CAMARINES NORTE | N20: ABRA | O20: PILAR | P20: 2812
A21: 10 | J21: CAMARINES SUR | N21: ABRA | O21: SALLAPADAN | P21: 2818
A22: 11 | J22: CAMIGUIN | N22: ABRA | O22: SAN ISIDRO | P22: 2809
A23: 12 | J23: CAPIZ | N23: ABRA | O23: SAN JUAN | P23: 2823
A24: 13 | J24: CATANDUANES | N24: ABRA | O24: SAN QUINTIN | P24: 2808
A25: 14 | J25: CAVITE | N25: ABRA | O25: TAYUM | P25: 2803
A26: 15 | J26: CEBU | N26: ABRA | O26: TINEG | P26: 2822
A27: 16 | J27: COMPOSTELA VALLEY | N27: ABRA | O27: TUBO | P27: 2814
A28: 17 | J28: COTABATO CITY | N28: ABRA | O28: VILLAVICIOSA | P28: 2811
... A47: 36 | J47: MANILA | N47: AGUSAN DEL SUR | O47: ROSARIO | P47: 8504
J48: MARINDUQUE | N48: AGUSAN DEL SUR | O48: SAN FRANCISCO | P48: 8501
J49: MASBATE | N49: AGUSAN DEL SUR | O49: SAN LUIS | P49: 8511
J50: MISAMIS OCCIDENTAL | N50: AGUSAN DEL SUR | O50: SANTA JOSEFA | P50: 8512
J51: MISAMIS ORIENTAL | N51: AGUSAN DEL SUR | O51: SIBAGAT | P51: 8503
J52: MOUNTAIN PROVINCE | N52: AGUSAN DEL SUR | O52: TALACOGON | P52: 8510
J53: NCR | N53: AGUSAN DEL SUR | O53: TRENTO | P53: 8505
A54: 43 mo | J54: NEGROS OCCIDENTAL | N54: AGUSAN DEL SUR | O54: VERUELA | P54: 8509
A55: 44 mo | J55: NEGROS ORIENTAL | N55: AKLAN | O55: ALTAVAS | P55: 5616
A56: 45 mo | J56: NORTH COTABATO | N56: AKLAN | O56: BALETE | P56: 5614
A57: 46 mo | J57: NORTHERN SAMAR | N57: AKLAN | O57: BANGA | P57: 5601
A58: 47 mo | J58: NUEVA ECIJA | N58: AKLAN | O58: BATAN | P58: 5615
...

Sheet Rates
B1: LRI (NEL) | C1: LRI NO NEL | D1: ADD | E1: AMR | F1: ABE | G1: UMA | H1: BA | I1: MCY | J1: FA | K1: DHIB | M1: TNPAX | N1: TSI | O1: TNP | P1: TGP | R1: NO. OF PAX
A2: 36 | B2: 24.82 | C2: 12.78 | D2: =D26*3 -> 0.75 | E2: =E26*3 -> 0 | F2: =F26*3 -> 1.5 | G2: =G26*3 -> 0.375 | H2: =H26*3 -> 11.4 | I2: =I26*3 -> 0.375 | J2: =J26*3 -> 0 | K2: =K26*3 -> 0 | M2: =SUM(R2:R10001) -> 0 | N2: =SUM(List!R2:R1048576) -> 0 | O2: =SUM(List!AX2:AX1000) -> 0 | P2: =SUM(List!BC2:BC1000) -> 0 | R2: =IF(List!B2="","",1)
A3: 35 | B3: 24.4 | C3: 12.57 | D3: =D26*2.95 -> 0.7375 | E3: =E26*2.95 -> 0 | F3: =F26*2.95 -> 1.475 | G3: =G26*2.95 -> 0.36875 | H3: =H26*2.95 -> 11.21 | I3: =I26*2.95 -> 0.36875 | J3: =J26*2.95 -> 0 | K3: =K26*2.95 -> 0 | R3: =IF(List!B3="","",1)
A4: 34 | B4: 23.99 | C4: 12.36 | D4: =D26*2.9 -> 0.725 | E4: =E26*2.9 -> 0 | F4: =F26*2.9 -> 1.45 | G4: =G26*2.9 -> 0.3625 | H4: =H26*2.9 -> 11.02 | I4: =I26*2.9 -> 0.3625 | J4: =J26*2.9 -> 0 | K4: =K26*2.9 -> 0 | M4: COVERAGE | R4: =IF(List!B4="","",1)
A5: 33 | B5: 23.57 | C5: 12.14 | D5: =D26*2.85 -> 0.7125 | E5: =E26*2.85 -> 0 | F5: =F26*2.85 -> 1.425 | G5: =G26*2.85 -> 0.35625 | H5: =H26*2.85 -> 10.83 | I5: =I26*2.85 -> 0.35625 | J5: =J26*2.85 -> 0 | K5: =K26*2.85 -> 0 | M5: ADD | N5: 50000 | R5: =IF(List!B5="","",1)
A6: 32 | B6: 23.16 | C6: 11.93 | D6: =D26*2.8 -> 0.7 | E6: =E26*2.8 -> 0 | F6: =F26*2.8 -> 1.4 | G6: =G26*2.8 -> 0.35 | H6: =H26*2.8 -> 10.64 | I6: =I26*2.8 -> 0.35 | J6: =J26*2.8 -> 0 | K6: =K26*2.8 -> 0 | M6: MR | N6: 5000 | R6: =IF(List!B6="","",1)
A7: 31 | B7: 22.75 | C7: 11.72 | D7: =D26*2.75 -> 0.6875 | E7: =E26*2.75 -> 0 | F7: =F26*2.75 -> 1.375 | G7: =G26*2.75 -> 0.34375 | H7: =H26*2.75 -> 10.45 | I7: =I26*2.75 -> 0.34375 | J7: =J26*2.75 -> 0 | K7: =K26*2.75 -> 0 | M7: ABE | N7: 5000 | P7: TAX COMPUTATION | R7: =IF(List!B7="","",1)
A8: 30 | B8: 22.33 | C8: 11.51 | D8: =D26*2.7 -> 0.675 | E8: =E26*2.7 -> 0 | F8: =F26*2.7 -> 1.35 | G8: =G26*2.7 -> 0.3375 | H8: =H26*2.7 -> 10.26 | I8: =I26*2.7 -> 0.3375 | J8: =J26*2.7 -> 0 | K8: =K26*2.7 -> 0 | M8: UMA | N8: =N5 -> 50000 | P8: =P2-Q15 -> 0 | R8: =IF(List!B8="","",1)
A9: 29 | B9: 21.51 | C9: 11.08 | D9: =D26*2.6 -> 0.65 | E9: =E26*2.6 -> 0 | F9: =F26*2.6 -> 1.3 | G9: =G26*2.6 -> 0.325 | H9: =H26*2.6 -> 9.88 | I9: =I26*2.6 -> 0.325 | J9: =J26*2.6 -> 0 | K9: =K26*2.6 -> 0 | M9: BA | N9: 10000 | P9: =P8/(1+0.025) -> 0 | R9: =IF(List!B9="","",1)
A10: 28 | B10: 20.68 | C10: 10.65 | D10: =D26*2.5 -> 0.625 | E10: =E26*2.5 -> 0 | F10: =F26*2.5 -> 1.25 | G10: =G26*2.5 -> 0.3125 | H10: =H26*2.5 -> 9.5 | I10: =I26*2.5 -> 0.3125 | J10: =J26*2.5 -> 0 | K10: =K26*2.5 -> 0 | M10: MCY | N10: =N5/2 -> 25000 | P10: =P9*0.025 -> 0 | R10: =IF(List!B10="","",1)
A11: 27 | B11: 19.85 | C11: 10.23 | D11: =D26*2.4 -> 0.6 | E11: =E26*2.4 -> 0 | F11: =F26*2.4 -> 1.2 | G11: =G26*2.4 -> 0.3 | H11: =H26*2.4 -> 9.12 | I11: =I26*2.4 -> 0.3 | J11: =J26*2.4 -> 0 | K11: =K26*2.4 -> 0 | M11: FA | R11: =IF(List!B11="","",1)
A12: 26 | B12: 19.03 | C12: 9.8 | D12: =D26*2.3 -> 0.575 | E12: =E26*2.3 -> 0 | F12: =F26*2.3 -> 1.15 | G12: =G26*2.3 -> 0.2875 | H12: =H26*2.3 -> 8.74 | I12: =I26*2.3 -> 0.2875 | J12: =J26*2.3 -> 0 | K12: =K26*2.3 -> 0 | M12: DHIB | R12: =IF(List!B12="","",1)
A13: 25 | B13: 18.2 | C13: 9.37 | D13: =D26*2.2 -> 0.55 | E13: =E26*2.2 -> 0 | F13: =F26*2.2 -> 1.1 | G13: =G26*2.2 -> 0.275 | H13: =H26*2.2 -> 8.36 | I13: =I26*2.2 -> 0.275 | J13: =J26*2.2 -> 0 | K13: =K26*2.2 -> 0 | R13: =IF(List!B13="","",1)
A14: 24 | B14: 16.54 | C14: 8.52 | D14: =D26*2 -> 0.5 | E14: =E26*2 -> 0 | F14: =F26*2 -> 1 | G14: =G26*2 -> 0.25 | H14: =H26*2 -> 7.6 | I14: =I26*2 -> 0.25 | J14: =J26*2 -> 0 | K14: =K26*2 -> 0 | M14: TAX PER PERSON | P14: TOTAL TAX | R14: =IF(List!B14="","",1)
A15: 23 | B15: 16.13 | C15: 8.31 | D15: =D26*1.95 -> 0.4875 | E15: =E26*1.95 -> 0 | F15: =F26*1.95 -> 0.975 | G15: =G26*1.95 -> 0.24375 | H15: =H26*1.95 -> 7.41 | I15: =I26*1.95 -> 0.24375 | J15: =J26*1.95 -> 0 | K15: =K26*1.95 -> 0 | M15: DST | N15: =Q15/M2 -> #DIV/0! | P15: DST | Q15: =IF(N2<=100000,0,IF(AND(N2>100000,N2<=300000),20,IF(AND(N2>300000,N2<=500000),50,IF(AND(N2>500000,N2<=750000),100,IF(AND(N2>750000,N2<=1000000),150,200))))) -> 0 | R15: =IF(List!B15="","",1)
A16: 22 | B16: 15.72 | C16: 8.1 | D16: =D26*1.9 -> 0.475 | E16: =E26*1.9 -> 0 | F16: =F26*1.9 -> 0.95 | G16: =G26*1.9 -> 0.2375 | H16: =H26*1.9 -> 7.22 | I16: =I26*1.9 -> 0.2375 | J16: =J26*1.9 -> 0 | K16: =K26*1.9 -> 0 | M16: PTAX | N16: =Q16/M2 -> #DIV/0! | P16: PTAX AND LGT | Q16: =O2*2.5% -> 0 | R16: =IF(List!B16="","",1)
A17: 21 | B17: 15.3 | C17: 7.88 | D17: =D26*1.85 -> 0.4625 | E17: =E26*1.85 -> 0 | F17: =F26*1.85 -> 0.925 | G17: =G26*1.85 -> 0.23125 | H17: =H26*1.85 -> 7.03 | I17: =I26*1.85 -> 0.23125 | J17: =J26*1.85 -> 0 | K17: =K26*1.85 -> 0 | M17: LGT | N17: =Q17/M2 -> #DIV/0! | R17: =IF(List!B17="","",1)
A18: 20 | B18: 14.89 | C18: 7.67 | D18: =D26*1.8 -> 0.45 | E18: =E26*1.8 -> 0 | F18: =F26*1.8 -> 0.9 | G18: =G26*1.8 -> 0.225 | H18: =H26*1.8 -> 6.84 | I18: =I26*1.8 -> 0.225 | J18: =J26*1.8 -> 0 | K18: =K26*1.8 -> 0 | R18: =IF(List!B18="","",1)
A19: 19 | B19: 14.48 | C19: 7.46 | D19: =D26*1.75 -> 0.4375 | E19: =E26*1.75 -> 0 | F19: =F26*1.75 -> 0.875 | G19: =G26*1.75 -> 0.21875 | H19: =H26*1.75 -> 6.65 | I19: =I26*1.75 -> 0.21875 | J19: =J26*1.75 -> 0 | K19: =K26*1.75 -> 0 | R19: =IF(List!B19="","",1)
A20: 18 | B20: 14.06 | C20: 7.24 | D20: =D26*1.7 -> 0.425 | E20: =E26*1.7 -> 0 | F20: =F26*1.7 -> 0.85 | G20: =G26*1.7 -> 0.2125 | H20: =H26*1.7 -> 6.46 | I20: =I26*1.7 -> 0.2125 | J20: =J26*1.7 -> 0 | K20: =K26*1.7 -> 0 | M20: COOPERATIVE? | N20: Yes | R20: =IF(List!B20="","",1)
A21: 17 | B21: 13.24 | C21: 6.82 | D21: =D26*1.6 -> 0.4 | E21: =E26*1.6 -> 0 | F21: =F26*1.6 -> 0.8 | G21: =G26*1.6 -> 0.2 | H21: =H26*1.6 -> 6.08 | I21: =I26*1.6 -> 0.2 | J21: =J26*1.6 -> 0 | K21: =K26*1.6 -> 0 | M21: SO | N21: Bacolod | R21: =IF(List!B21="","",1)
A22: 16 | B22: 12.41 | C22: 6.39 | D22: =D26*1.5 -> 0.375 | E22: =E26*1.5 -> 0 | F22: =F26*1.5 -> 0.75 | G22: =G26*1.5 -> 0.1875 | H22: =H26*1.5 -> 5.7 | I22: =I26*1.5 -> 0.1875 | J22: =J26*1.5 -> 0 | K22: =K26*1.5 -> 0 | M22: SO RATE | N22: =VLOOKUP(N21,M31:N46,2,0) -> 0.005 | R22: =IF(List!B22="","",1)
A23: 15 | B23: 11.58 | C23: 5.97 | D23: =D26*1.4 -> 0.35 | E23: =E26*1.4 -> 0 | F23: =F26*1.4 -> 0.7 | G23: =G26*1.4 -> 0.175 | H23: =H26*1.4 -> 5.32 | I23: =I26*1.4 -> 0.175 | J23: =J26*1.4 -> 0 | K23: =K26*1.4 -> 0 | R23: =IF(List!B23="","",1)
A24: 14 | B24: 10.75 | C24: 5.54 | D24: =D26*1.3 -> 0.325 | E24: =E26*1.3 -> 0 | F24: =F26*1.3 -> 0.65 | G24: =G26*1.3 -> 0.1625 | H24: =H26*1.3 -> 4.94 | I24: =I26*1.3 -> 0.1625 | J24: =J26*1.3 -> 0 | K24: =K26*1.3 -> 0 | R24: =IF(List!B24="","",1)
A25: 13 | B25: 9.93 | C25: 5.11 | D25: =D26*1.2 -> 0.3 | E25: =E26*1.2 -> 0 | F25: =F26*1.2 -> 0.6 | G25: =G26*1.2 -> 0.15 | H25: =H26*1.2 -> 4.56 | I25: =I26*1.2 -> 0.15 | J25: =J26*1.2 -> 0 | K25: =K26*1.2 -> 0 | L25: LRI | M25: ADD | N25: ABE | O25: UMA | P25: BA | Q25: MCY | R25: AMR
A26: 12 | B26: 8.27 | C26: 4.26 | D26: 0.25 | F26: 0.5 | G26: 0.125 | H26: 3.8 | I26: 0.125 | M26: =D26/B26 -> 0.030229746 | N26: =M26 -> 0.030229746 | O26: =G26/B26 -> 0.015114873 | P26: =(H26/B26)/2 -> 0.22974607 | Q26: =I26/B26 -> 0.015114873 | R26: =IF(List!B26="","",1)
A27: 11 | B27: 7.86 | C27: 4.05 | D27: =D26*0.95 -> 0.2375 | E27: =E26*0.95 -> 0 | F27: =F26*0.95 -> 0.475 | G27: =G26*0.95 -> 0.11875 | H27: =H26*0.95 -> 3.61 | I27: =I26*0.95 -> 0.11875 | J27: =J26*0.95 -> 0 | K27: =K26*0.95 -> 0 | R27: =IF(List!B27="","",1)
A28: 10 | B28: 7.44 | C28: 3.84 | D28: =D26*0.9 -> 0.225 | E28: =E26*0.9 -> 0 | F28: =F26*0.9 -> 0.45 | G28: =G26*0.9 -> 0.1125 | H28: =H26*0.9 -> 3.42 | I28: =I26*0.9 -> 0.1125 | J28: =J26*0.9 -> 0 | K28: =K26*0.9 -> 0 | R28: =IF(List!B28="","",1)
A29: 9 | B29: 7.03 | C29: 3.62 | D29: =D26*0.85 -> 0.2125 | E29: =E26*0.85 -> 0 | F29: =F26*0.85 -> 0.425 | G29: =G26*0.85 -> 0.10625 | H29: =H26*0.85 -> 3.23 | I29: =I26*0.85 -> 0.10625 | J29: =J26*0.85 -> 0 | K29: =K26*0.85 -> 0 | R29: =IF(List!B29="","",1)
A30: 8 | B30: 6.62 | C30: 3.41 | D30: =D26*0.8 -> 0.2 | E30: =E26*0.8 -> 0 | F30: =F26*0.8 -> 0.4 | G30: =G26*0.8 -> 0.1 | H30: =H26*0.8 -> 3.04 | I30: =I26*0.8 -> 0.1 | J30: =J26*0.8 -> 0 | K30: =K26*0.8 -> 0 | M30: SALES OFFICE | N30: LGT RATE | R30: =IF(List!B30="","",1)
A31: 7 | B31: 6.2 | C31: 3.2 | D31: =D26*0.75 -> 0.1875 | E31: =E26*0.75 -> 0 | F31: =F26*0.75 -> 0.375 | G31: =G26*0.75 -> 0.09375 | H31: =H26*0.75 -> 2.85 | I31: =I26*0.75 -> 0.09375 | J31: =J26*0.75 -> 0 | K31: =K26*0.75 -> 0 | M31: Alabang | N31: 0.005 | R31: =IF(List!B31="","",1)
A32: 6 | B32: 5.79 | C32: 2.98 | D32: =D26*0.7 -> 0.175 | E32: =E26*0.7 -> 0 | F32: =F26*0.7 -> 0.35 | G32: =G26*0.7 -> 0.0875 | H32: =H26*0.7 -> 2.66 | I32: =I26*0.7 -> 0.0875 | J32: =J26*0.7 -> 0 | K32: =K26*0.7 -> 0 | M32: Bacolod | N32: 0.005 | R32: =IF(List!B32="","",1)
A33: 5 | B33: 4.96 | C33: 2.56 | D33: =D26*0.6 -> 0.15 | E33: =E26*0.6 -> 0 | F33: =F26*0.6 -> 0.3 | G33: =G26*0.6 -> 0.075 | H33: =H26*0.6 -> 2.28 | I33: =I26*0.6 -> 0.075 | J33: =J26*0.6 -> 0 | K33: =K26*0.6 -> 0 | M33: CDO | N33: 0.0075 | R33: =IF(List!B33="","",1)
A34: 4 | B34: 4.14 | C34: 2.13 | D34: =D26*0.5 -> 0.125 | E34: =E26*0.5 -> 0 | F34: =F26*0.5 -> 0.25 | G34: =G26*0.5 -> 0.0625 | H34: =H26*0.5 -> 1.9 | I34: =I26*0.5 -> 0.0625 | J34: =J26*0.5 -> 0 | K34: =K26*0.5 -> 0 | M34: Cebu | N34: 0.005 | R34: =IF(List!B34="","",1)
A35: 3 | B35: 3.31 | C35: 1.7 | D35: =D26*0.4 -> 0.1 | E35: =E26*0.4 -> 0 | F35: =F26*0.4 -> 0.2 | G35: =G26*0.4 -> 0.05 | H35: =H26*0.4 -> 1.52 | I35: =I26*0.4 -> 0.05 | J35: =J26*0.4 -> 0 | K35: =K26*0.4 -> 0 | M35: Davao | N35: 0.006 | R35: =IF(List!B35="","",1)
A36: 2 | B36: 2.48 | C36: 1.28 | D36: =D26*0.3 -> 0.075 | E36: =E26*0.3 -> 0 | F36: =F26*0.3 -> 0.15 | G36: =G26*0.3 -> 0.0375 | H36: =H26*0.3 -> 1.14 | I36: =I26*0.3 -> 0.0375 | J36: =J26*0.3 -> 0 | K36: =K26*0.3 -> 0 | M36: EDSA Caloocan | N36: 0.0027 | R36: =IF(List!B36="","",1)
A37: 1 | B37: 1.65 | C37: 0.85 | D37: =D26*0.2 -> 0.05 | E37: =E26*0.2 -> 0 | F37: =F26*0.2 -> 0.1 | G37: =G26*0.2 -> 0.025 | H37: =H26*0.2 -> 0.76 | I37: =I26*0.2 -> 0.025 | J37: =J26*0.2 -> 0 | K37: =K26*0.2 -> 0 | M37: Iloilo | N37: 0.005 | R37: =IF(List!B37="","",1)
M38: Las Pinas | N38: 0.0055 | R38: =IF(List!B38="","",1)
M39: Lipa | N39: 0.005 | R39: =IF(List!B39="","",1)
M40: Makati | N40: 0.002 | R40: =IF(List!B40="","",1)
...
